<?xml version="1.0" ?>
<robot
  name="XM">
  <link
    name="base_link">
    <inertial>
      <origin
        xyz="-0.0018926 -0.038457 -0.021634"
        rpy="0 0 0" />
      <mass
        value="20.64" />
      <inertia
        ixx="2.1701"
        ixy="-0.0041401"
        ixz="-0.00026473"
        iyy="0.43845"
        iyz="0.12519"
        izz="2.1677" />
    </inertial>
    <visual>
      <origin
        xyz="0 0 0"
        rpy="0 0 0" />
      <geometry>
        <mesh
          filename="package://XM/meshes/base_link.STL" />
      </geometry>
      <material
        name="">
        <color
          rgba="0.75294 0.75294 0.75294 1" />
      </material>
    </visual>
    <collision>
      <origin
        xyz="0 0 0"
        rpy="0 0 0" />
      <geometry>
        <mesh
          filename="package://XM/meshes/base_link.STL" />
      </geometry>
    </collision>
  </link>
  <link
    name="lifting_Link">
    <inertial>
      <origin
        xyz="-2.034E-10 -0.044467 0.074678"
        rpy="0 0 0" />
      <mass
        value="4.139" />
      <inertia
        ixx="0.023514"
        ixy="-2.476E-11"
        ixz="-6.8567E-11"
        iyy="0.020683"
        iyz="-0.0074192"
        izz="0.017083" />
    </inertial>
    <visual>
      <origin
        xyz="0 0 0"
        rpy="0 0 0" />
      <geometry>
        <mesh
          filename="package://XM/meshes/lifting_Link.STL" />
      </geometry>
      <material
        name="">
        <color
          rgba="1 0.91765 0.8 1" />
      </material>
    </visual>
    <collision>
      <origin
        xyz="0 0 0"
        rpy="0 0 0" />
      <geometry>
        <mesh
          filename="package://XM/meshes/lifting_Link.STL" />
      </geometry>
    </collision>
  </link>
  <joint
    name="joint_lifting"
    type="prismatic">
    <origin
      xyz="0.00028281 -0.25402 -0.043734"
      rpy="3.6317E-26 -0.0064665 3.904E-40" />
    <parent
      link="base_link" />
    <child
      link="lifting_Link" />
    <axis
      xyz="0 1 0" />
    <limit
      lower="0.05"
      upper="0.45"
      effort="0"
      velocity="0" />
  </joint>
  <link
    name="waist_Link">
    <inertial>
      <origin
        xyz="0.0020934 -0.02078 0.0092904"
        rpy="0 0 0" />
      <mass
        value="1.8049" />
      <inertia
        ixx="0.015768"
        ixy="-0.0002136"
        ixz="-0.00036488"
        iyy="0.0079986"
        iyz="-0.0018608"
        izz="0.014015" />
    </inertial>
    <visual>
      <origin
        xyz="0 0 0"
        rpy="0 0 0" />
      <geometry>
        <mesh
          filename="package://XM/meshes/waist_Link.STL" />
      </geometry>
      <material
        name="">
        <color
          rgba="0.5 1 0.8 1" />
      </material>
    </visual>
    <collision>
      <origin
        xyz="0 0 0"
        rpy="0 0 0" />
      <geometry>
        <mesh
          filename="package://XM/meshes/waist_Link.STL" />
      </geometry>
    </collision>
  </link>
  <joint
    name="joint_waist"
    type="revolute">
    <origin
      xyz="0 -0.2218 0.136"
      rpy="-2.8496E-16 -1.075E-14 7.3949E-16" />
    <parent
      link="lifting_Link" />
    <child
      link="waist_Link" />
    <axis
      xyz="0 1 0" />
    <limit
      lower="-1.57"
      upper="1.57"
      effort="0"
      velocity="0" />
  </joint>
  <link
    name="big_arm_Link">
    <inertial>
      <origin
        xyz="0.00048507 -0.0037941 0.12763"
        rpy="0 0 0" />
      <mass
        value="1.3414" />
      <inertia
        ixx="0.014476"
        ixy="1.4256E-05"
        ixz="-8.8774E-05"
        iyy="0.017027"
        iyz="0.00033307"
        izz="0.0040217" />
    </inertial>
    <visual>
      <origin
        xyz="0 0 0"
        rpy="0 0 0" />
      <geometry>
        <mesh
          filename="package://XM/meshes/big_arm_Link.STL" />
      </geometry>
      <material
        name="">
        <color
          rgba="0.7 1 0.4 1" />
      </material>
    </visual>
    <collision>
      <origin
        xyz="0 0 0"
        rpy="0 0 0" />
      <geometry>
        <mesh
          filename="package://XM/meshes/big_arm_Link.STL" />
      </geometry>
    </collision>
  </link>
  <joint
    name="joinr_big_arm"
    type="revolute">
    <origin
      xyz="0 -0.12547 0.13033"
      rpy="0 7.9736E-15 4.2111E-33" />
    <parent
      link="waist_Link" />
    <child
      link="big_arm_Link" />
    <axis
      xyz="1 0 0" />
    <limit
      lower="-1.57"
      upper="1.57"
      effort="0"
      velocity="0" />
  </joint>
  <link
    name="fore_arm_Link">
    <inertial>
      <origin
        xyz="0.00031488 0.00077015 0.082927"
        rpy="0 0 0" />
      <mass
        value="0.66536" />
      <inertia
        ixx="0.0062497"
        ixy="-1.6576E-05"
        ixz="-0.00025384"
        iyy="0.0069348"
        iyz="4.5771E-05"
        izz="0.0010978" />
    </inertial>
    <visual>
      <origin
        xyz="0 0 0"
        rpy="0 0 0" />
      <geometry>
        <mesh
          filename="package://XM/meshes/fore_arm_Link.STL" />
      </geometry>
      <material
        name="">
        <color
          rgba="0.2 0.61961 1 1" />
      </material>
    </visual>
    <collision>
      <origin
        xyz="0 0 0"
        rpy="0 0 0" />
      <geometry>
        <mesh
          filename="package://XM/meshes/fore_arm_Link.STL" />
      </geometry>
    </collision>
  </link>
  <joint
    name="joint_fore_arm"
    type="revolute">
    <origin
      xyz="0 0 0.35"
      rpy="0 1.2212E-15 -4.2209E-32" />
    <parent
      link="big_arm_Link" />
    <child
      link="fore_arm_Link" />
    <axis
      xyz="-1 0 0" />
    <limit
      lower="-1.57"
      upper="1.57"
      effort="0"
      velocity="0" />
  </joint>
  <link
    name="wrist_Link">
    <inertial>
      <origin
        xyz="-0.0016964 -1.8874E-15 0.03193"
        rpy="0 0 0" />
      <mass
        value="0.21596" />
      <inertia
        ixx="0.00030788"
        ixy="7.5664E-18"
        ixz="8.084E-06"
        iyy="0.00068067"
        iyz="1.728E-17"
        izz="0.00041975" />
    </inertial>
    <visual>
      <origin
        xyz="0 0 0"
        rpy="0 0 0" />
      <geometry>
        <mesh
          filename="package://XM/meshes/wrist_Link.STL" />
      </geometry>
      <material
        name="">
        <color
          rgba="1 0.7 0.3 1" />
      </material>
    </visual>
    <collision>
      <origin
        xyz="0 0 0"
        rpy="0 0 0" />
      <geometry>
        <mesh
          filename="package://XM/meshes/wrist_Link.STL" />
      </geometry>
    </collision>
  </link>
  <joint
    name="joint_wrist"
    type="revolute">
    <origin
      xyz="0 0.0010002 0.25"
      rpy="0 0 -4.2209E-32" />
    <parent
      link="fore_arm_Link" />
    <child
      link="wrist_Link" />
    <axis
      xyz="1 0 0" />
    <limit
      lower="-1.57"
      upper="1.57"
      effort="0"
      velocity="0" />
  </joint>
  <link
    name="fore_joint_Link">
    <inertial>
      <origin
        xyz="-0.0037211 0.00074906 0.046928"
        rpy="0 0 0" />
      <mass
        value="0.36527" />
      <inertia
        ixx="0.00032887"
        ixy="-7.465E-06"
        ixz="-1.0886E-05"
        iyy="0.00072728"
        iyz="8.5383E-07"
        izz="0.0004828" />
    </inertial>
    <visual>
      <origin
        xyz="0 0 0"
        rpy="0 0 0" />
      <geometry>
        <mesh
          filename="package://XM/meshes/fore_joint_Link.STL" />
      </geometry>
      <material
        name="">
        <color
          rgba="1 0.8 0.54902 1" />
      </material>
    </visual>
    <collision>
      <origin
        xyz="0 0 0"
        rpy="0 0 0" />
      <geometry>
        <mesh
          filename="package://XM/meshes/fore_joint_Link.STL" />
      </geometry>
    </collision>
  </link>
  <joint
    name="fore_joint"
    type="revolute">
    <origin
      xyz="0.0044 0 0.093"
      rpy="0 -1.1102E-15 3.5848E-32" />
    <parent
      link="wrist_Link" />
    <child
      link="fore_joint_Link" />
    <axis
      xyz="0 0 1" />
    <limit
      lower="-1.57"
      upper="1.57"
      effort="0"
      velocity="0" />
  </joint>
  <link
    name="right_finger_Link">
    <inertial>
      <origin
        xyz="0.009058 -0.0045005 0.0073292"
        rpy="0 0 0" />
      <mass
        value="0.030707" />
      <inertia
        ixx="4.538E-05"
        ixy="-8.9082E-07"
        ixz="-5.2065E-06"
        iyy="4.4551E-05"
        iyz="6.4561E-06"
        izz="5.8119E-06" />
    </inertial>
    <visual>
      <origin
        xyz="0 0 0"
        rpy="0 0 0" />
      <geometry>
        <mesh
          filename="package://XM/meshes/right_finger_Link.STL" />
      </geometry>
      <material
        name="">
        <color
          rgba="0.89804 0.91765 0.92941 1" />
      </material>
    </visual>
    <collision>
      <origin
        xyz="0 0 0"
        rpy="0 0 0" />
      <geometry>
        <mesh
          filename="package://XM/meshes/right_finger_Link.STL" />
      </geometry>
    </collision>
  </link>
  <joint
    name="joint_right_finger"
    type="prismatic">
    <origin
      xyz="0.044912 -0.0015 0.11"
      rpy="2.8496E-16 -8.0846E-15 -6.3892E-16" />
    <parent
      link="fore_joint_Link" />
    <child
      link="right_finger_Link" />
    <axis
      xyz="-1 0 0" />
    <limit
      lower="-0.045"
      upper="0"
      effort="0"
      velocity="0" />
  </joint>
  <link
    name="left_finger_Link">
    <inertial>
      <origin
        xyz="-0.009058 -0.0045008 0.0073292"
        rpy="0 0 0" />
      <mass
        value="0.030707" />
      <inertia
        ixx="4.538E-05"
        ixy="8.9056E-07"
        ixz="5.2065E-06"
        iyy="4.4551E-05"
        iyz="6.456E-06"
        izz="5.8118E-06" />
    </inertial>
    <visual>
      <origin
        xyz="0 0 0"
        rpy="0 0 0" />
      <geometry>
        <mesh
          filename="package://XM/meshes/left_finger_Link.STL" />
      </geometry>
      <material
        name="">
        <color
          rgba="1 1 1 1" />
      </material>
    </visual>
    <collision>
      <origin
        xyz="0 0 0"
        rpy="0 0 0" />
      <geometry>
        <mesh
          filename="package://XM/meshes/left_finger_Link.STL" />
      </geometry>
    </collision>
  </link>
  <joint
    name="joint_left_finger"
    type="prismatic">
    <origin
      xyz="-0.044912 -0.0015 0.11"
      rpy="5.0701E-16 -8.0569E-15 -6.1702E-16" />
    <parent
      link="fore_joint_Link" />
    <child
      link="left_finger_Link" />
    <axis
      xyz="-1 0 0" />
    <limit
      lower="0"
      upper="0.045"
      effort="0"
      velocity="0" />
  </joint>
</robot>
