<robot
  name="xm_urdf">
  <link
    name="base_link">
    <inertial>
      <origin
        xyz="-0.058386 -0.00013422 0.2828"
        rpy="0 0 0" />
      <mass
        value="23.205" />
      <inertia
        ixx="2.2285"
        ixy="-0.00082892"
        ixz="-0.36687"
        iyy="2.2956"
        iyz="0.0012257"
        izz="0.67883" />
    </inertial>
    <visual>
      <origin
        xyz="0 0 0"
        rpy="0 0 0" />
      <geometry>
        <mesh
          filename="package://xm_urdf/meshes/base_link.STL" />
      </geometry>
      <material
        name="">
        <color
          rgba="0 0 1 1" />
      </material>
    </visual>
    <collision>
      <origin
        xyz="0 0 0"
        rpy="0 0 0" />
      <geometry>
        <mesh
          filename="package://xm_urdf/meshes/base_link.STL" />
      </geometry>
    </collision>
  </link>

<link name="base_footprint">
    <visual>
      <origin xyz="0 0 0" rpy="0 0 0" />
      <geometry>
        <box size="0.05 0.05 0.001" />
      </geometry>
         <material name="green">
            <color rgba="0.2 0.8 0.2 1.0"/>
         </material>   
    </visual>

    <collision>
      <origin xyz="0 0 0" rpy="0 0 0" />
      <geometry>
       <box size="0.001 0.001 0.001" />
      </geometry>
    </collision>
  </link>

  <joint name="Joint_base" type="fixed">
    <origin xyz="0 0 0 " rpy="0 0 0" />        
    <parent link="base_footprint"/>
    <child link="base_link" />
  </joint>

  <link
    name="laser_link" />
  <joint
    name="laser"
    type="fixed">
    <origin
      xyz="0.163974226119285 0 0.268"
      rpy="-1.22065831197831E-42 0 0" />
    <parent
      link="base_link" />
    <child
      link="laser_link" />
    <axis
      xyz="0 0 0" />
  </joint>
  <link
    name="camera_link">
    <inertial>
      <origin
        xyz="-2.8828E-17 0.00031293 -0.033699"
        rpy="0 0 0" />
      <mass
        value="0.70931" />
      <inertia
        ixx="0.00036711"
        ixy="3.2266E-18"
        ixz="-2.0721E-19"
        iyy="0.0039733"
        iyz="1.0991E-06"
        izz="0.0038203" />
    </inertial>
    <visual>
      <origin
        xyz="0 0 0"
        rpy="0 0 0" />
      <geometry>
        <mesh
          filename="package://xm_urdf/meshes/camera_Link.STL" />
      </geometry>
      <material
        name="">
        <color
          rgba="0.1 0.1 0.1 1" />
      </material>
    </visual>
    <collision>
      <origin
        xyz="0 0 0"
        rpy="0 0 0" />
      <geometry>
        <mesh
          filename="package://xm_urdf/meshes/camera_Link.STL" />
      </geometry>
    </collision>
  </link>
  <joint
    name="joint_camera"
    type="fixed">
    <origin
      xyz="-0.0598758126584776 0 1.16914083167556"
      rpy="1.5707963267949 1.51232771764078E-26 1.5707963267949" />
    <parent
      link="base_link" />
    <child
      link="camera_link" />
    <axis
      xyz="0 0 0" />
  </joint>
  <link
    name="lifting_link">
    <inertial>
      <origin
        xyz="0.11124 0.0011157 0.099709"
        rpy="0 0 0" />
      <mass
        value="4.2881" />
      <inertia
        ixx="0.030442"
        ixy="0.00027157"
        ixz="0.0060464"
        iyy="0.032612"
        iyz="6.5027E-06"
        izz="0.015696" />
    </inertial>
    <visual>
      <origin
        xyz="0 0 0"
        rpy="0 0 0" />
      <geometry>
        <mesh
          filename="package://xm_urdf/meshes/lifting_Link.STL" />
      </geometry>
      <material
        name="">
        <color
          rgba="0.89804 0.91765 0.92941 1" />
      </material>
    </visual>
    <collision>
      <origin
        xyz="0 0 0"
        rpy="0 0 0" />
      <geometry>
        <mesh
          filename="package://xm_urdf/meshes/lifting_Link.STL" />
      </geometry>
    </collision>
  </link>
  <joint
    name="joint_lifting"
    type="prismatic">
    <origin
      xyz="-0.114 0 0.43917"
      rpy="-1.2207E-42 0 0" />
    <parent
      link="base_link" />
    <child
      link="lifting_link" />
    <axis
      xyz="0 0 -1" />
    <limit
      lower="-0.08"
      upper="0.31"
      effort="0"
      velocity="0" />
  </joint>
  <link
    name="waist_link">
    <inertial>
      <origin
        xyz="0.080745 0.0062517 0.10329"
        rpy="0 0 0" />
      <mass
        value="0.88833" />
      <inertia
        ixx="0.0030962"
        ixy="-0.00042931"
        ixz="0.001727"
        iyy="0.0064304"
        iyz="-0.00023096"
        izz="0.0070683" />
    </inertial>
    <visual>
      <origin
        xyz="0 0 0"
        rpy="0 0 0" />
      <geometry>
        <mesh
          filename="package://xm_urdf/meshes/waist_Link.STL" />
      </geometry>
      <material
        name="">
        <color
          rgba="0.1 0.91765 0.92941 1" />
      </material>
    </visual>
    <collision>
      <origin
        xyz="0 0 0"
        rpy="0 0 0" />
      <geometry>
        <mesh
          filename="package://xm_urdf/meshes/waist_Link.STL" />
      </geometry>
    </collision>
  </link>
  <joint
    name="joint_waist"
    type="revolute">
    <origin
      xyz="0.136 0 0.2388"
      rpy="-1.2207E-42 0 0" />
    <parent
      link="lifting_link" />
    <child
      link="waist_link" />
    <axis
      xyz="0 0 -1" />
    <limit
      lower="-1.57"
      upper="1.57"
      effort="0"
      velocity="0" />
  </joint>
  <link
    name="big_arm_link">
    <inertial>
      <origin
        xyz="0.15858 0.0033783 0.0013137"
        rpy="0 0 0" />
      <mass
        value="0.42189" />
      <inertia
        ixx="0.00077473"
        ixy="0.0001978"
        ixz="-0.00011508"
        iyy="0.0044734"
        iyz="-1.3185E-05"
        izz="0.0048568" />
    </inertial>
    <visual>
      <origin
        xyz="0 0 0"
        rpy="0 0 0" />
      <geometry>
        <mesh
          filename="package://xm_urdf/meshes/big_arm_Link.STL" />
      </geometry>
      <material
        name="">
        <color
          rgba="0.89804 0.1 0.92941 1" />
      </material>
    </visual>
    <collision>
      <origin
        xyz="0 0 0"
        rpy="0 0 0" />
      <geometry>
        <mesh
          filename="package://xm_urdf/meshes/big_arm_Link.STL" />
      </geometry>
    </collision>
  </link>
  <joint
    name="joint_big_arm"
    type="revolute">
    <origin
      xyz="0.15 -0.024 0.12996"
      rpy="-1.2207E-42 1.3825E-32 0" />
    <parent
      link="waist_link" />
    <child
      link="big_arm_link" />
    <axis
      xyz="0 -1 0" />
    <limit
      lower="-1.57"
      upper="1.57"
      effort="0"
      velocity="0" />
  </joint>
  <link
    name="fore_arm_link">
    <inertial>
      <origin
        xyz="0.093108 -0.0019364 -0.0003252"
        rpy="0 0 0" />
      <mass
        value="0.24897" />
      <inertia
        ixx="0.00032386"
        ixy="-5.3655E-05"
        ixz="1.7477E-07"
        iyy="0.00095578"
        iyz="-2.918E-06"
        izz="0.0011682" />
    </inertial>
    <visual>
      <origin
        xyz="0 0 0"
        rpy="0 0 0" />
      <geometry>
        <mesh
          filename="package://xm_urdf/meshes/fore_arm_Link.STL" />
      </geometry>
      <material
        name="">
        <color
          rgba="0.89804 0.91765 0.1 1" />
      </material>
    </visual>
    <collision>
      <origin
        xyz="0 0 0"
        rpy="0 0 0" />
      <geometry>
        <mesh
          filename="package://xm_urdf/meshes/fore_arm_Link.STL" />
      </geometry>
    </collision>
  </link>
  <joint
    name="joint_fore_arm"
    type="revolute">
    <origin
      xyz="0.28 0.024 -0.002"
      rpy="-1.2207E-42 -1.3825E-32 0" />
    <parent
      link="big_arm_link" />
    <child
      link="fore_arm_link" />
    <axis
      xyz="0 -1 0" />
    <limit
      lower="-1.57"
      upper="1.57"
      effort="0"
      velocity="0" />
  </joint>
  <link
    name="wrist_link">
    <inertial>
      <origin
        xyz="0.054228 -0.00038117 -0.0021816"
        rpy="0 0 0" />
      <mass
        value="0.13591" />
      <inertia
        ixx="0.00027415"
        ixy="-1.2603E-06"
        ixz="-6.1922E-06"
        iyy="0.00022407"
        iyz="5.0705E-08"
        izz="0.00042781" />
    </inertial>
    <visual>
      <origin
        xyz="0 0 0"
        rpy="0 0 0" />
      <geometry>
        <mesh
          filename="package://xm_urdf/meshes/wrist_Link.STL" />
      </geometry>
      <material
        name="">
        <color
          rgba="0.89804 0.1 0.1 1" />
      </material>
    </visual>
    <collision>
      <origin
        xyz="0 0 0"
        rpy="0 0 0" />
      <geometry>
        <mesh
          filename="package://xm_urdf/meshes/wrist_Link.STL" />
      </geometry>
    </collision>
  </link>
  <joint
    name="joint_wrist"
    type="revolute">
    <origin
      xyz="0.15 0 0"
      rpy="-1.2207E-42 1.3825E-32 0" />
    <parent
      link="fore_arm_link" />
    <child
      link="wrist_link" />
    <axis
      xyz="0 -1 0" />
    <limit
      lower="-2.2"
      upper="2.2"
      effort="0"
      velocity="0" />
  </joint>
  <link
    name="small_arm_link">
    <inertial>
      <origin
        xyz="0.04591 0.00086039 -0.0012881"
        rpy="0 0 0" />
      <mass
        value="0.27505" />
      <inertia
        ixx="0.00041798"
        ixy="2.1193E-06"
        ixz="-7.3544E-06"
        iyy="0.00030554"
        iyz="-1.3497E-06"
        izz="0.00066992" />
    </inertial>
    <visual>
      <origin
        xyz="0 0 0"
        rpy="0 0 0" />
      <geometry>
        <mesh
          filename="package://xm_urdf/meshes/small_arm_Link.STL" />
      </geometry>
      <material
        name="">
        <color
          rgba="0.52941 0.54902 0.54902 1" />
      </material>
    </visual>
    <collision>
      <origin
        xyz="0 0 0"
        rpy="0 0 0" />
      <geometry>
        <mesh
          filename="package://xm_urdf/meshes/small_arm_Link.STL" />
      </geometry>
    </collision>
  </link>
  <joint
    name="joint_small_arm"
    type="revolute">
    <origin
      xyz="0.094923 0 -0.0038189"
      rpy="-1.2207E-42 -1.3825E-32 0" />
    <parent
      link="wrist_link" />
    <child
      link="small_arm_link" />
    <axis
      xyz="-0.99919 0 0.040198" />
    <limit
      lower="-1.57"
      upper="1.57"
      effort="0"
      velocity="0" />
  </joint>
  <link
    name="right_finger_link">
    <inertial>
      <origin
        xyz="0.014381 -0.0066887 -0.00069344"
        rpy="0 0 0" />
      <mass
        value="0.02641" />
      <inertia
        ixx="4.7848E-06"
        ixy="4.1444E-06"
        ixz="-2.7231E-06"
        iyy="2.7792E-05"
        iyz="-5.6496E-07"
        izz="2.8388E-05" />
    </inertial>
    <visual>
      <origin
        xyz="0 0 0"
        rpy="0 0 0" />
      <geometry>
        <mesh
          filename="package://xm_urdf/meshes/right_finger_Link.STL" />
      </geometry>
      <material
        name="">
        <color
          rgba="1 0.5 1 1" />
      </material>
    </visual>
    <collision>
      <origin
        xyz="0 0 0"
        rpy="0 0 0" />
      <geometry>
        <mesh
          filename="package://xm_urdf/meshes/right_finger_Link.STL" />
      </geometry>
    </collision>
  </link>
  <joint
    name="joint_right_finger"
    type="prismatic">
    <origin
      xyz="0.11192 -0.020688 -0.0020008"
      rpy="-1.2207E-42 1.3825E-32 0" />
    <parent
      link="small_arm_link" />
    <child
      link="right_finger_link" />
    <axis
      xyz="0 1 0" />
    <limit
      lower="-0.06"
      upper="0"
      effort="0"
      velocity="0" />
  </joint>
  <link
    name="left_finger_link">
    <inertial>
      <origin
        xyz="0.014381 0.0066887 -0.00069344"
        rpy="0 0 0" />
      <mass
        value="0.02641" />
      <inertia
        ixx="4.7848E-06"
        ixy="-4.1444E-06"
        ixz="-2.7231E-06"
        iyy="2.7792E-05"
        iyz="5.6496E-07"
        izz="2.8388E-05" />
    </inertial>
    <visual>
      <origin
        xyz="0 0 0"
        rpy="0 0 0" />
      <geometry>
        <mesh
          filename="package://xm_urdf/meshes/left_finger_Link.STL" />
      </geometry>
      <material
        name="">
        <color
          rgba="0.3 1 1 1" />
      </material>
    </visual>
    <collision>
      <origin
        xyz="0 0 0"
        rpy="0 0 0" />
      <geometry>
        <mesh
          filename="package://xm_urdf/meshes/left_finger_Link.STL" />
      </geometry>
    </collision>
  </link>
  <joint
    name="joint_left_finger"
    type="prismatic">
    <origin
      xyz="0.11192 0.020688 -0.0020008"
      rpy="-1.2207E-42 1.3825E-32 0" />
    <parent
      link="small_arm_link" />
    <child
      link="left_finger_link" />
    <axis
      xyz="0 1 0" />
    <limit
      lower="0"
      upper="0.06"
      effort="0"
      velocity="0" />
  </joint>

<joint name="joint_gripper" type="fixed">
    <origin rpy="0 0 0" xyz="0.250 0 0"/>
    <parent link="small_arm_link"/>
    <child link="gripper_link"/>
  </joint>

  <link name="gripper_link">
    <visual>
      <origin rpy="0 0 0" xyz="-0.05 0 0"/>
      <geometry>
        <box size="0.001 0.001 0.001"/>
      </geometry>
    </visual>
    <collision>
      <origin rpy="0 0 0" xyz="-0.05 0 0"/>
      <geometry>
        <box size="0.001 0.001 0.001"/>
      </geometry>
    </collision>
    <!--inertial>
         <mass value="0.0012" />
         <origin xyz="0 0 0"/>
         <inertia ixx="2e-8" ixy="0.0" ixz="0.0"
          iyy="2e-8" iyz="0.0"
          izz="2e-8" />
      </inertial -->
  </link>
</robot>
